Workbook

Sheet sumry
C3: أسعار المواد | F3: أجور التنفيذ | J3: أسعار المواد | M3: أجور التنفيذ | Q3: سعر الصرف
C4: سعر طن الحديد | D4: 12 + 14 mm | E4: 645 | F4: النجار | G4: متر مكعب | H4: =O4/$Q$4 -> 11.344538 | J4: سعر طن الحديد | K4: 12 + 14 mm | L4: =E4*$Q$4 -> 7675500 | M4: النجار | N4: متر مكعب | O4: 135000 | Q4: 11900
D5: 8 + 10 mm | E5: 680 | G5: متر طولي | H5: =O5/$Q$4 -> 3.7815126 | K5: 8 + 10 mm | L5: =E5*$Q$4 -> 8092000 | N5: متر طولي | O5: =O4/3 -> 45000
D6: 6 mm | E6: 710 | G6: عامود | H6: =O6/$Q$4 -> 11.344538 | K6: 6 mm | L6: =E6*$Q$4 -> 8449000 | N6: عامود | O6: 135000
C7: سعر طن الاسمنت | E7: 130 | G7: درج | H7: =O7/$Q$4 -> 168.06723 | J7: سعر طن الاسمنت | L7: =E7*$Q$4 -> 1547000 | N7: درج | O7: 2000000
C8: سعر متر الرمل + البحص | E8: =L8/$Q$4 -> 13.445378 | F8: الصب | G8: القواعد | H8: =O8/$Q$4 -> 168.06723 | J8: سعر متر الرمل + البحص | L8: 160000 | M8: الصب | N8: القواعد | O8: 2000000
C9: سعر بلوكة الهوردي | E9: =L9/$Q$4 -> 0.46218487 | G9: الشيناج | H9: =O9/$Q$4 -> 168.06723 | J9: سعر بلوكة الهوردي | L9: 5500 | N9: الشيناج | O9: 2000000
C10: سعر بلوكة البناء | E10: =L10/$Q$4 -> 0.29411765 | G10: السطح | H10: =O10/$Q$4 -> 210.08403 | J10: سعر بلوكة البناء | L10: 3500 | N10: السطح | O10: 2500000
C11: سعر متر رمل البناء | E11: =L11/$Q$4 -> 15.966387 | G11: العامود | H11: =O11/$Q$4 -> 16.806723 | J11: سعر متر رمل البناء | L11: 190000 | N11: العامود | O11: 200000
C13: جدول الكلفة الإجمالي $ | H13: جدول الكميات الإجمالي | P13: تفاصيل كميات الحديد | S13: تشاريك الحديد
C14: البند | D14: كلفة المواد | E14: أجور التنفيذ | F14: الإجمالي | H14: البند | I14: الأسمنت | J14: الحديد | K14: البحص / الرمل | L14: بلوك الهوردي | M14: بلوك البناء | N14: رمل البناء | P14: 6 mm | Q14: =Columns!T16+Beams!S14+Slaps!P9+Slaps!T35 -> 0.512 | S14: البند | T14: التشريكة | U14: عدد التشاريك | V14: قطر القضيب | W14: طول القضيب | X14: عدد القطع ضمن الضيب | Y14: الزيادة في كل قضيب | Z14: عدد القضبان اللازم | AA14: الزيادات | AB14: الوزن
C15: الحفر + الردم | D15: =Excavation!G5*Excavation!J13/Q4 -> 0 | E15: =Excavation!F13-sumry!D15 -> 0 | F15: =E15+D15 -> 0 | H15: الحفر + الردم | I15: 0 | J15: 0 | K15: 0 | L15: 0 | M15: 0 | N15: 0 | P15: 8 mm | Q15: =Columns!R16+Beams!Q14+Slaps!N9+Slaps!R35 -> 0.816 | S15: الأعمدة | T15: 4 | U15: =8*8+10*8+6*6 -> 180 | V15: 12 | W15: =IF(V15=6,6,12) -> 12 | X15: =ROUNDDOWN(IF(T15=0,0,W15/T15),0) -> 3 | Y15: =IF(T15=0,0,W15-X15*T15) -> 0 | Z15: =IF(X15=0,0,ROUNDUP(U15/X15,0)) -> 60 | AA15: =IF(Y15=0,"1 * "&ROUND(AC15,1),Z15&" * "&ROUNDUP(Y15,1)) -> 1 * 0 | AB15: =Z15*W15*0.89 -> 640.8
C16: القواعد | D16: =Foundation!C18+Foundation!C19+Foundation!C20 -> 0 | E16: =Foundation!C21 -> 0 | F16: =E16+D16 -> 0 | H16: القواعد | I16: =Foundation!I14 -> 0 | J16: =Foundation!S14 -> 0 | K16: =Foundation!J14 -> 0 | L16: 0 | M16: 0 | N16: 0 | P16: 10 mm | Q16: =Slaps!L9+Slaps!P35 -> 0 | T16: 3.5 | U16: 0 | V16: 12 | W16: =IF(V16=6,6,12) -> 12 | X16: =ROUNDDOWN(IF(T16=0,0,W16/T16),0) -> 3 | Y16: =IF(T16=0,0,W16-X16*T16) -> 1.5 | Z16: =IF(X16=0,0,ROUNDUP(U16/X16,0)) -> 0 | AA16: =IF(Y16=0,"1 * "&ROUND(AC16,1),Z16&" * "&ROUNDUP(Y16,1)) -> 0 * 1.5 | AB16: =Z16*W16*0.89 -> 0
C17: الأعمدة | D17: =Columns!D20+Columns!D21+Columns!D22 -> 1505.5295 | E17: =Columns!D23 -> 675.63025 | F17: =E17+D17 -> 2181.1597 | H17: الأعمدة | I17: =Columns!K16 -> 5.056 | J17: =Columns!U16 -> 0.982 | K17: =Columns!L16 -> 15.168 | L17: 0 | M17: 0 | N17: 0 | P17: 12 mm | Q17: =Foundation!O14+Columns!P16+Slaps!J9+Slaps!N35+Beams!O14+Stairs!M16 -> 2.580338 | T17: 0 | U17: 0 | V17: 12 | W17: =IF(V17=6,6,12) -> 12 | X17: =ROUNDDOWN(IF(T17=0,0,W17/T17),0) -> 0 | Y17: =IF(T17=0,0,W17-X17*T17) -> 0 | Z17: =IF(X17=0,0,ROUNDUP(U17/X17,0)) -> 0 | AA17: =IF(Y17=0,"1 * "&ROUND(AC17,1),Z17&" * "&ROUNDUP(Y17,1)) -> 1 * 0
C18: الشيناج | D18: =Beams!D18+Beams!D19+Beams!D20 -> 0 | E18: =Beams!D21 -> 0 | F18: =E18+D18 -> 0 | H18: الشيناج | I18: =Beams!J14 -> 0 | J18: =Beams!T14 -> 0 | K18: =Beams!K14 -> 0 | L18: 0 | M18: 0 | N18: 0 | P18: 14 mm | Q18: =Foundation!R14+Columns!N16+Beams!M14+Slaps!L35 -> 0 | AB18: =SUM(AB15:AB17) -> 640.8
C19: الأرضية | D19: =Slaps!D12+Slaps!D13+Slaps!D14 -> 0 | E19: =Slaps!D15 -> 0 | F19: =E19+D19 -> 0 | H19: الأرضية | I19: =Slaps!G9 -> 0 | J19: =Slaps!Q8 -> 0 | K19: =Slaps!H9 -> 0 | L19: 0 | M19: 0 | N19: 0
C20: الدرج | D20: =Stairs!D20+Stairs!D21+Stairs!D22 -> 230.10901 | E20: =Stairs!D23 -> 218.06723 | F20: =D20+E20 -> 448.17624 | H20: الدرج | I20: =Stairs!L9 -> 0.83664 | J20: =Stairs!M16 -> 0.128338 | K20: =Stairs!M9 -> 2.86848 | L20: 0 | M20: 0 | N20: 0 | T20: 8.75 | U20: 21 | V20: 12 | W20: =IF(V20=6,6,12) -> 12 | X20: =ROUNDDOWN(IF(T20=0,0,W20/T20),0) -> 1 | Y20: =IF(T20=0,0,W20-X20*T20) -> 3.25 | Z20: =IF(X20=0,0,ROUNDUP(U20/X20,0)) -> 21 | AA20: =IF(Y20=0,"1 * "&ROUND(AC20,1),Z20&" * "&ROUNDUP(Y20,1)) -> 21 * 3.3 | AB20: =Z20*W20*0.89 -> 224.28 | AC20: 20
C21: السطح | D21: =Slaps!D39+Slaps!D40+Slaps!D41+Slaps!D42 -> 4441.4153 | E21: =Slaps!D43 -> 594.5771 | F21: =E21+D21 -> 5035.9924 | H21: السطح | I21: =Slaps!I35 -> 11.862323 | J21: =Slaps!U35 -> 2.798 | K21: =Slaps!J35 -> 40.670822 | L21: =Slaps!G35 -> 1075 | M21: 0 | N21: 0 | T21: 7.3 | U21: 15 | V21: 12 | W21: =IF(V21=6,6,12) -> 12 | X21: =ROUNDDOWN(IF(T21=0,0,W21/T21),0) -> 1 | Y21: =IF(T21=0,0,W21-X21*T21) -> 4.7 | Z21: =IF(X21=0,0,ROUNDUP(U21/X21,0)) -> 15 | AA21: =IF(Y21=0,"1 * "&ROUND(AC21,1),Z21&" * "&ROUNDUP(Y21,1)) -> 15 * 4.7 | AB21: =Z21*W21*0.89 -> 160.2 | AC21: 15
C22: البلوك | D22: =Bricks!D25+Bricks!D26+Bricks!D27 -> 0 | E22: =Bricks!D28 -> 0 | F22: =E22+D22 -> 0 | H22: البلوك | I22: =Bricks!N21 -> 0 | J22: 0 | K22: 0 | L22: 0 | M22: =Bricks!L21 -> 0 | N22: =Bricks!O21 -> 0 | T22: 6 | U22: 15 | V22: 12 | W22: =IF(V22=6,6,12) -> 12 | X22: =ROUNDDOWN(IF(T22=0,0,W22/T22),0) -> 2 | Y22: =IF(T22=0,0,W22-X22*T22) -> 0 | Z22: =IF(X22=0,0,ROUNDUP(U22/X22,0)) -> 8 | AA22: =IF(Y22=0,"1 * "&ROUND(AC22,1),Z22&" * "&ROUNDUP(Y22,1)) -> 1 * 0 | AB22: =Z22*W22*0.89 -> 85.44
C23: الطينة | D23: =Plastering!D29+Plastering!D30 -> 0 | E23: =Plastering!D31 -> 0 | F23: =E23+D23 -> 0 | H23: الطينة | I23: =Plastering!J25 -> 0 | J23: 0 | K23: 0 | L23: 0 | M23: 0 | N23: =Plastering!K25 -> 0 | T23: 4.7 | U23: 6 | V23: 12 | W23: =IF(V23=6,6,12) -> 12 | X23: =ROUNDDOWN(IF(T23=0,0,W23/T23),0) -> 2 | Y23: =IF(T23=0,0,W23-X23*T23) -> 2.6 | Z23: =IF(X23=0,0,ROUNDUP(U23/X23,0)) -> 3 | AA23: =IF(Y23=0,"1 * "&ROUND(AC23,1),Z23&" * "&ROUNDUP(Y23,1)) -> 3 * 2.6 | AB23: =Z23*W23*0.89 -> 32.04
C24: الإجمالي | D24: =SUM(D15:D23) -> 6177.0538 | E24: =SUM(E15:E23) -> 1488.2746 | F24: =ROUNDUP(SUM(F15:F23),-2)+50+100+150+100 -> 8100 | H24: الإجمالي | I24: =SUM(I15:I23) -> 17.754963 | J24: =SUM(J15:J23) -> 3.908338 | K24: =SUM(K15:K23) -> 58.707302 | L24: =SUM(L15:L23) -> 1075 | M24: =SUM(M15:M23) -> 0 | N24: =SUM(N15:N23) -> 0 | T24: 3 | U24: 0 | V24: 12 | W24: =IF(V24=6,6,12) -> 12 | X24: =ROUNDDOWN(IF(T24=0,0,W24/T24),0) -> 4 | Y24: =IF(T24=0,0,W24-X24*T24) -> 0 | Z24: =IF(X24=0,0,ROUNDUP(U24/X24,0)) -> 0 | AA24: =IF(Y24=0,"1 * "&ROUND(AC24,1),Z24&" * "&ROUNDUP(Y24,1)) -> 1 * 0 | AB24: =Z24*W24*0.89 -> 0
T25: 5.7 | U25: 12 | V25: 12 | W25: =IF(V25=6,6,12) -> 12 | X25: =ROUNDDOWN(IF(T25=0,0,W25/T25),0) -> 2 | Y25: =IF(T25=0,0,W25-X25*T25) -> 0.6 | Z25: =IF(X25=0,0,ROUNDUP(U25/X25,0)) -> 6 | AA25: =IF(Y25=0,"1 * "&ROUND(AC25,1),Z25&" * "&ROUNDUP(Y25,1)) -> 6 * 0.6 | AB25: =Z25*W25*0.89 -> 64.08
H26: =SUM(I26:N26) -> 6177.0538 | I26: =I24*E7 -> 2308.1452 | J26: =Q14*E6+Q15*E5+Q16*E5+Q17*E4+Q18*E4 -> 2582.718 | K26: =K24*E8 -> 789.34188 | L26: =L24*E9 -> 496.84874 | M26: =M24*E10 -> 0 | N26: =N24*E11 -> 0 | T26: 4.4 | U26: 12 | V26: 12 | W26: =IF(V26=6,6,12) -> 12 | X26: =ROUNDDOWN(IF(T26=0,0,W26/T26),0) -> 2 | Y26: =IF(T26=0,0,W26-X26*T26) -> 3.2 | Z26: =IF(X26=0,0,ROUNDUP(U26/X26,0)) -> 6 | AA26: =IF(Y26=0,"1 * "&ROUND(AC26,1),Z26&" * "&ROUNDUP(Y26,1)) -> 6 * 3.2 | AB26: =Z26*W26*0.89 -> 64.08 | AC26: 4
AB27: =SUM(AB20:AB26) -> 630.12
T28: 12 | U28: 6 | V28: 12 | W28: =IF(V28=6,6,12) -> 12 | X28: =ROUNDDOWN(IF(T28=0,0,W28/T28),0) -> 1 | Y28: =IF(T28=0,0,W28-X28*T28) -> 0 | Z28: =IF(X28=0,0,ROUNDUP(U28/X28,0)) -> 6 | AA28: =IF(Y28=0,"1 * "&ROUND(AC28,1),Z28&" * "&ROUNDUP(Y28,1)) -> 1 * 0 | AB28: =Z28*W28*0.89 -> 64.08
C29: جدول الكلفة الإجمالي ل.س | T29: 10 | U29: 12 | V29: 12 | W29: =IF(V29=6,6,12) -> 12 | X29: =ROUNDDOWN(IF(T29=0,0,W29/T29),0) -> 1 | Y29: =IF(T29=0,0,W29-X29*T29) -> 2 | Z29: =IF(X29=0,0,ROUNDUP(U29/X29,0)) -> 12 | AA29: =IF(Y29=0,"1 * "&ROUND(AC29,1),Z29&" * "&ROUNDUP(Y29,1)) -> 12 * 2 | AB29: =Z29*W29*0.89 -> 128.16 | AC29: 4
C30: البند | D30: كلفة المواد | E30: أجور التنفيذ | F30: الإجمالي | T30: 5 | U30: 6 | V30: 12 | W30: =IF(V30=6,6,12) -> 12 | X30: =ROUNDDOWN(IF(T30=0,0,W30/T30),0) -> 2 | Y30: =IF(T30=0,0,W30-X30*T30) -> 2 | Z30: =IF(X30=0,0,ROUNDUP(U30/X30,0)) -> 3 | AA30: =IF(Y30=0,"1 * "&ROUND(AC30,1),Z30&" * "&ROUNDUP(Y30,1)) -> 3 * 2 | AB30: =Z30*W30*0.89 -> 32.04
C31: الحفر + الردم | D31: =D15*$Q$4 -> 0 | E31: =E15*$Q$4 -> 0 | F31: =F15*$Q$4 -> 0 | T31: 3.5 | U31: 0 | V31: 12 | W31: =IF(V31=6,6,12) -> 12 | X31: =ROUNDDOWN(IF(T31=0,0,W31/T31),0) -> 3 | Y31: =IF(T31=0,0,W31-X31*T31) -> 1.5 | Z31: =IF(X31=0,0,ROUNDUP(U31/X31,0)) -> 0 | AA31: =IF(Y31=0,"1 * "&ROUND(AC31,1),Z31&" * "&ROUNDUP(Y31,1)) -> 0 * 1.5 | AB31: =Z31*W31*0.89 -> 0
C32: القواعد | D32: =D16*$Q$4 -> 0 | E32: =E16*$Q$4 -> 0 | F32: =F16*$Q$4 -> 0 | T32: 5.75 | U32: 7 | V32: 12 | W32: =IF(V32=6,6,12) -> 12 | X32: =ROUNDDOWN(IF(T32=0,0,W32/T32),0) -> 2 | Y32: =IF(T32=0,0,W32-X32*T32) -> 0.5 | Z32: =IF(X32=0,0,ROUNDUP(U32/X32,0)) -> 4 | AA32: =IF(Y32=0,"1 * "&ROUND(AC32,1),Z32&" * "&ROUNDUP(Y32,1)) -> 4 * 0.5 | AB32: =Z32*W32*0.89 -> 42.72
C33: الأعمدة | D33: =D17*$Q$4 -> 17915801 | E33: =E17*$Q$4 -> 8040000 | F33: =F17*$Q$4 -> 25955801 | T33: 5.55 | U33: 6 | V33: 12 | W33: =IF(V33=6,6,12) -> 12 | X33: =ROUNDDOWN(IF(T33=0,0,W33/T33),0) -> 2 | Y33: =IF(T33=0,0,W33-X33*T33) -> 0.9 | Z33: =IF(X33=0,0,ROUNDUP(U33/X33,0)) -> 3 | AA33: =IF(Y33=0,"1 * "&ROUND(AC33,1),Z33&" * "&ROUNDUP(Y33,1)) -> 3 * 0.9 | AB33: =Z33*W33*0.89 -> 32.04
C34: الشيناج | D34: =D18*$Q$4 -> 0 | E34: =E18*$Q$4 -> 0 | F34: =F18*$Q$4 -> 0 | AB34: =SUM(AB28:AB33) -> 299.04
C35: الأرضية | D35: =D19*$Q$4 -> 0 | E35: =E19*$Q$4 -> 0 | F35: =F19*$Q$4 -> 0 | T35: 11 | U35: 6 | V35: 12 | W35: =IF(V35=6,6,12) -> 12 | X35: =ROUNDDOWN(IF(T35=0,0,W35/T35),0) -> 1 | Y35: =IF(T35=0,0,W35-X35*T35) -> 1 | Z35: =IF(X35=0,0,ROUNDUP(U35/X35,0)) -> 6 | AA35: =IF(Y35=0,"1 * "&ROUND(AC35,1),Z35&" * "&ROUNDUP(Y35,1)) -> 6 * 1 | AB35: =Z35*W35*0.89 -> 64.08
C36: الدرج | D36: =D20*$Q$4 -> 2738297.2 | E36: =E20*$Q$4 -> 2595000 | F36: =F20*$Q$4 -> 5333297.2 | T36: 10 | U36: 12 | V36: 12 | W36: =IF(V36=6,6,12) -> 12 | X36: =ROUNDDOWN(IF(T36=0,0,W36/T36),0) -> 1 | Y36: =IF(T36=0,0,W36-X36*T36) -> 2 | Z36: =IF(X36=0,0,ROUNDUP(U36/X36,0)) -> 12 | AA36: =IF(Y36=0,"1 * "&ROUND(AC36,1),Z36&" * "&ROUNDUP(Y36,1)) -> 12 * 2 | AB36: =Z36*W36*0.89 -> 128.16
C37: السطح | D37: =D21*$Q$4 -> 52852843 | E37: =E21*$Q$4 -> 7075467.5 | F37: =F21*$Q$4 -> 59928310 | T37: 6 | U37: 30 | V37: 12 | W37: =IF(V37=6,6,12) -> 12 | X37: =ROUNDDOWN(IF(T37=0,0,W37/T37),0) -> 2 | Y37: =IF(T37=0,0,W37-X37*T37) -> 0 | Z37: =IF(X37=0,0,ROUNDUP(U37/X37,0)) -> 15 | AA37: =IF(Y37=0,"1 * "&ROUND(AC37,1),Z37&" * "&ROUNDUP(Y37,1)) -> 1 * 0 | AB37: =Z37*W37*0.89 -> 160.2
C38: البلوك | D38: =D22*$Q$4 -> 0 | E38: =E22*$Q$4 -> 0 | F38: =F22*$Q$4 -> 0 | T38: 3.5 | U38: 12 | V38: 12 | W38: =IF(V38=6,6,12) -> 12 | X38: =ROUNDDOWN(IF(T38=0,0,W38/T38),0) -> 3 | Y38: =IF(T38=0,0,W38-X38*T38) -> 1.5 | Z38: =IF(X38=0,0,ROUNDUP(U38/X38,0)) -> 4 | AA38: =IF(Y38=0,"1 * "&ROUND(AC38,1),Z38&" * "&ROUNDUP(Y38,1)) -> 4 * 1.5 | AB38: =Z38*W38*0.89 -> 42.72
C39: الطينة | D39: =D23*Q4 -> 0 | E39: =E23*$Q$4 -> 0 | F39: =F23*$Q$4 -> 0 | T39: 5.6 | U39: 21 | V39: 12 | W39: =IF(V39=6,6,12) -> 12 | X39: =ROUNDDOWN(IF(T39=0,0,W39/T39),0) -> 2 | Y39: =IF(T39=0,0,W39-X39*T39) -> 0.8 | Z39: =IF(X39=0,0,ROUNDUP(U39/X39,0)) -> 11 | AA39: =IF(Y39=0,"1 * "&ROUND(AC39,1),Z39&" * "&ROUNDUP(Y39,1)) -> 11 * 0.9 | AB39: =Z39*W39*0.89 -> 117.48
C40: الإجمالي | D40: =D24*Q4 -> 73506941 | E40: =E24*$Q$4 -> 17710468 | F40: =F24*$Q$4 -> 96390000 | T40: 11 | U40: 12 | V40: 12 | W40: =IF(V40=6,6,12) -> 12 | X40: =ROUNDDOWN(IF(T40=0,0,W40/T40),0) -> 1 | Y40: =IF(T40=0,0,W40-X40*T40) -> 1 | Z40: =IF(X40=0,0,ROUNDUP(U40/X40,0)) -> 12 | AA40: =IF(Y40=0,"1 * "&ROUND(AC40,1),Z40&" * "&ROUNDUP(Y40,1)) -> 12 * 1 | AB40: =Z40*W40*0.89 -> 128.16
T41: 10 | U41: 24 | V41: 12 | W41: =IF(V41=6,6,12) -> 12 | X41: =ROUNDDOWN(IF(T41=0,0,W41/T41),0) -> 1 | Y41: =IF(T41=0,0,W41-X41*T41) -> 2 | Z41: =IF(X41=0,0,ROUNDUP(U41/X41,0)) -> 24 | AA41: =IF(Y41=0,"1 * "&ROUND(AC41,1),Z41&" * "&ROUNDUP(Y41,1)) -> 24 * 2 | AB41: =Z41*W41*0.89 -> 256.32
T42: 3.5 | U42: 24 | V42: 12 | W42: =IF(V42=6,6,12) -> 12 | X42: =ROUNDDOWN(IF(T42=0,0,W42/T42),0) -> 3 | Y42: =IF(T42=0,0,W42-X42*T42) -> 1.5 | Z42: =IF(X42=0,0,ROUNDUP(U42/X42,0)) -> 8 | AA42: =IF(Y42=0,"1 * "&ROUND(AC42,1),Z42&" * "&ROUNDUP(Y42,1)) -> 8 * 1.5 | AB42: =Z42*W42*0.89 -> 85.44
AB43: =SUM(AB35:AB42) -> 982.56
...

Sheet Excavation
C3: الحفر + الردم | J3: الأجور
C4: متوسط عمق الحفر | D4: عدد القواعد | E4: كمية الحفر | F4: عدد ساعات الردم قبل الشيناج | G4: كمية الردم اللازمة بعد الشيناج | H4: عدد ساعات الردم بعد الشيناج | J4: متر الحفر
C5: 0 | D5: 0 | E5: 0 | F5: 0 | G5: 0 | H5: 0 | J5: 60000
J6: تنظيف القاعدة
E7: الكلفة التفصيلية | J7: 50000
E8: الحفر | F8: =E5*J5/sumry!Q4 -> 0 | J8: ترحيل القاعدة
E9: الترحيل | F9: =D5*0.5*C5*J9/sumry!Q4 -> 0 | J9: 50000
E10: التنظيف | F10: =D5*J7/sumry!Q4 -> 0 | J10: ساعة الردم
E11: الردم قبل الشيناج | F11: =F5*J11/sumry!Q4 -> 0 | J11: 250000
E12: الردم بعد الشيناج | F12: =(G5*J13+H5*J11)/sumry!Q4 -> 0 | J12: متر الردم
E13: الكلفة الاجمالية | F13: =F12+F8+F9+F10+F11 -> 0 | J13: 30000

Sheet Foundation
B3: القواعد
B4: البيتون | K4: الحديد
B5: القاعدة | C5: الأبعاد | F5: حجم القاعدة | G5: عدد القواعد | H5: الحجم الكلي | I5: كمية الاسمنت اللازمة | J5: بحص + رمل | K5: التسليح الرئيسي | O5: التسليح الثانوي | S5: اجمالي كمية التسليح
C6: الطول | D6: العرض | E6: السماكة | K6: عدد الاسياخ | L6: طول السيخ | M6: القطر | N6: كمية التسليح | O6: عدد الاسياخ | P6: طول السيخ | Q6: القطر | R6: كمية التسليح
C7: cm | D7: cm | E7: cm | F7: m3 | G7: n | H7: m3 | I7: ton | J7: m3 | K7: n | L7: m | M7: mm | N7: kg | O7: n | P7: m | Q7: mm | R7: kg | S7: ton
B8: F1 | C8: 0 | D8: 0 | E8: 0 | F8: =E8*D8*C8/1000000 -> 0 | G8: 0 | H8: =F8*G8 -> 0 | I8: =H8*7/20 -> 0 | J8: =H8*1.2 -> 0 | K8: 3 | L8: =IF(E8=0,0,(D8+D8+E8+E8-30)/100) -> 0 | M8: 14 | N8: =ROUNDUP(IF(M8=14,K8*G8*L8*1.2,IF(M8=16,K8*G8*L8*1.59,K8*G8*L8*0.89)),0) -> 0 | O8: 2 | P8: =IF(E8=0,0,(C8+C8-30+E8+E8)/100) -> 0 | Q8: 14 | R8: =ROUNDUP(IF(Q8=14,O8*G8*P8*1.2,IF(Q8=16,O8*G8*P8*1.59,O8*P8*G8*0.89)),0) -> 0 | S8: =(R8+R9+N8+N9)/1000 -> 0
K9: 6 | L9: =IF(D8=0,0,(D8-15+50)/100) -> 0 | M9: 14 | N9: =ROUNDUP(IF(M9=14,K9*G8*L9*1.2,IF(M9=16,K9*G8*L9*1.59,K9*G8*L9*0.89)),0) -> 0 | O9: 5 | P9: =IF(E8=0,0,(C8-15+50)/100) -> 0 | Q9: 14 | R9: =ROUNDUP(IF(Q9=14,O9*G8*P9*1.2,IF(Q9=16,O9*G8*P9*1.59,O9*P9*G8*0.89)),0) -> 0
B10: F2 | C10: 0 | D10: 0 | E10: 0 | F10: =E10*D10*C10/1000000 -> 0 | G10: 0 | H10: =F10*G10 -> 0 | I10: =H10*7/20 -> 0 | J10: =H10*1.2 -> 0 | K10: 0 | L10: =IF(E10=0,0,(D10+D10+E10+E10-30)/100) -> 0 | M10: 12 | N10: =ROUNDUP(IF(M10=14,K10*G10*L10*1.2,IF(M10=16,K10*G10*L10*1.59,K10*G10*L10*0.89)),0) -> 0 | O10: 0 | P10: =IF(E10=0,0,(C10+C10-30+E10+E10)/100) -> 0 | Q10: 12 | R10: =ROUNDUP(IF(Q10=14,O10*G10*P10*1.2,IF(Q10=16,O10*G10*P10*1.59,O10*P10*G10*0.89)),0) -> 0 | S10: =(R10+R11+N10+N11)/1000 -> 0
K11: 0 | L11: =IF(D10=0,0,(D10-15+50)/100) -> 0 | M11: 12 | N11: =ROUNDUP(IF(M11=14,K11*G10*L11*1.2,IF(M11=16,K11*G10*L11*1.59,K11*G10*L11*0.89)),0) -> 0 | O11: 0 | P11: =IF(E10=0,0,(C10-15+50)/100) -> 0 | Q11: 12 | R11: =ROUNDUP(IF(Q11=14,O11*G10*P11*1.2,IF(Q11=16,O11*G10*P11*1.59,O11*P11*G10*0.89)),0) -> 0
B12: F3 | C12: 0 | D12: 0 | E12: 0 | F12: =E12*D12*C12/1000000 -> 0 | G12: 0 | H12: =F12*G12 -> 0 | I12: =H12*7/20 -> 0 | J12: =H12*1.2 -> 0 | K12: 0 | L12: =IF(E12=0,0,(D12+D12+E12+E12-30)/100) -> 0 | M12: 12 | N12: =ROUNDUP(IF(M12=14,K12*G12*L12*1.2,IF(M12=16,K12*G12*L12*1.59,K12*G12*L12*0.89)),0) -> 0 | O12: 0 | P12: =IF(E12=0,0,(C12+C12-30+E12+E12)/100) -> 0 | Q12: 12 | R12: =ROUNDUP(IF(Q12=14,O12*G12*P12*1.2,IF(Q12=16,O12*G12*P12*1.59,O12*P12*G12*0.89)),0) -> 0 | S12: =(R12+R13+N12+N13)/1000 -> 0
K13: 0 | L13: =IF(D12=0,0,(D12-15+50)/100) -> 0 | M13: 12 | N13: =ROUNDUP(IF(M13=14,K13*G12*L13*1.2,IF(M13=16,K13*G12*L13*1.59,K13*G12*L13*0.89)),0) -> 0 | O13: 0 | P13: =IF(E12=0,0,(C12-15+50)/100) -> 0 | Q13: 12 | R13: =ROUNDUP(IF(Q13=14,O13*G12*P13*1.2,IF(Q13=16,O13*G12*P13*1.59,O13*P13*G12*0.89)),0) -> 0
C14: الإجمالي | H14: =SUM(H8:H12) -> 0 | I14: =SUM(I8:I12) -> 0 | J14: =ROUNDUP(SUM(J8:J12),0) -> 0 | K14: الإجمالي | N14: 12 mm | O14: =SUMIF(M8:M13,"12",N8:N13)/1000 + SUMIF(Q8:Q13,"12",R8:R13)/1000 -> 0 | Q14: 14 mm | R14: =SUMIF(M8:M13,"14",N8:N13)/1000 + SUMIF(Q8:Q13,"14",R8:R13)/1000 -> 0 | S14: =SUM(S8:S13) -> 0
B17: الكلفة التفصيلية
B18: اسمنت | C18: =I14*sumry!E7 -> 0
B19: بحص / رمل | C19: =J14*sumry!E8 -> 0
B20: حديد | C20: =S14*sumry!E4 -> 0
B21: تنفيذ | C21: =IF(H14=0,0,H14*sumry!H4+sumry!H8) -> 0
B22: الإجمالي | C22: =SUM(C18:C21) -> 0

Sheet Columns
C3: الأعمدة
C4: البيتون | M4: الحديد
C5: الطابق | D5: العامود | E5: الأبعاد | H5: حجم العامود | I5: عدد الاعمدة | J5: الحجم الكلي | K5: كمية الاسمنت اللازمة | L5: بحص + رمل | M5: التسليح الرئيسي | Q5: التسليح الثانوي | U5: اجمالي كمية التسليح
E6: الطول | F6: العرض | G6: الارتفاع | M6: عدد الاسياخ | N6: طول السيخ | O6: القطر | P6: كمية التسليح | Q6: عدد الاسياخ | R6: طول السيخ | S6: القطر | T6: كمية التسليح
E7: cm | F7: cm | G7: cm | H7: m3 | I7: n | J7: m3 | K7: ton | L7: m3 | M7: n | N7: m | O7: mm | P7: kg | Q7: n | R7: m | S7: mm | T7: kg | U7: ton
C8: الأول | D8: c1 | E8: 80 | F8: 25 | G8: 320 | H8: =G8*F8*E8/1000000 -> 0.64 | I8: 6 | J8: =H8*I8 -> 3.84 | K8: =J8*8/20 -> 1.536 | L8: =J8*1.2 -> 4.608 | M8: 10 | N8: 4 | O8: 12 | P8: =ROUNDUP(IF(O8=14,M8*I8*N8*1.2,IF(O8=16,M8*I8*N8*1.59,M8*I8*N8*0.89)),0) -> 214 | Q8: 20 | R8: 1.9 | S8: 8 | T8: =ROUNDUP(IF(S8=6,Q8*I8*R8*0.22,IF(S8=10,Q8*I8*R8*0.62,Q8*R8*I8*0.4)),0) -> 92 | U8: =(T8+T9+P8+P9)/1000 -> 0.391
D9: c2 | E9: 70 | F9: 25 | G9: 320 | H9: =G9*F9*E9/1000000 -> 0.56 | I9: 2 | J9: =H9*I9 -> 1.12 | K9: =J9*8/20 -> 0.448 | L9: =J9*1.2 -> 1.344 | M9: 8 | N9: 4 | O9: 12 | P9: =ROUNDUP(IF(O9=14,M9*I9*N9*1.2,IF(O9=16,M9*I9*N9*1.59,M9*I9*N9*0.89)),0) -> 57 | Q9: 20 | R9: 1.7 | S9: 8 | T9: =ROUNDUP(IF(S9=6,Q9*I9*R9*0.22,IF(S9=10,Q9*I9*R9*0.62,Q9*R9*I9*0.4)),0) -> 28
C10: الثاني | D10: c1 | E10: 60 | F10: 25 | G10: 320 | H10: =G10*F10*E10/1000000 -> 0.48 | I10: 8 | J10: =H10*I10 -> 3.84 | K10: =J10*8/20 -> 1.536 | L10: =J10*1.2 -> 4.608 | M10: 8 | N10: 4 | O10: 12 | P10: =ROUNDUP(IF(O10=14,M10*I10*N10*1.2,IF(O10=16,M10*I10*N10*1.59,M10*I10*N10*0.89)),0) -> 228 | Q10: 20 | R10: 1.5 | S10: 8 | T10: =ROUNDUP(IF(S10=6,Q10*I10*R10*0.22,IF(S10=10,Q10*I10*R10*0.62,Q10*R10*I10*0.4)),0) -> 96 | U10: =(T10+T11+P10+P11)/1000 -> 0.591
D11: c2 | E11: 60 | F11: 25 | G11: 320 | H11: =G11*F11*E11/1000000 -> 0.48 | I11: 8 | J11: =H11*I11 -> 3.84 | K11: =J11*8/20 -> 1.536 | L11: =J11*1.2 -> 4.608 | M11: 6 | N11: 4 | O11: 12 | P11: =ROUNDUP(IF(O11=14,M11*I11*N11*1.2,IF(O11=16,M11*I11*N11*1.59,M11*I11*N11*0.89)),0) -> 171 | Q11: 20 | R11: 1.5 | S11: 8 | T11: =ROUNDUP(IF(S11=6,Q11*I11*R11*0.22,IF(S11=10,Q11*I11*R11*0.62,Q11*R11*I11*0.4)),0) -> 96
C12: الأول | D12: c1 | E12: 0 | F12: 0 | G12: 0 | H12: =G12*F12*E12/1000000 -> 0 | I12: 0 | J12: =H12*I12 -> 0 | K12: =J12*8/20 -> 0 | L12: =J12*1.2 -> 0 | M12: 0 | N12: =IF(G12=0,0,G12/100+1) -> 0 | O12: 12 | P12: =ROUNDUP(IF(O12=14,M12*I12*N12*1.2,IF(O12=16,M12*I12*N12*1.59,M12*I12*N12*0.89)),0) -> 0 | Q12: 0 | R12: =(E12+E12+F12+F12)/100 -> 0 | S12: 8 | T12: =ROUNDUP(IF(S12=6,Q12*I12*R12*0.22,IF(S12=10,Q12*I12*R12*0.62,Q12*R12*I12*0.4)),0) -> 0 | U12: =(T12+T13+P12+P13)/1000 -> 0
D13: - | E13: 0 | F13: 0 | G13: 0 | H13: =G13*F13*E13/1000000 -> 0 | I13: 0 | J13: =H13*I13 -> 0 | K13: =J13*8/20 -> 0 | L13: =J13*1.2 -> 0 | M13: 0 | N13: =IF(G13=0,0,G13/100+1) -> 0 | O13: 12 | P13: =ROUNDUP(IF(O13=14,M13*I12*N13*1.2,IF(O13=16,M13*I12*N13*1.59,M13*I12*N13*0.89)),0) -> 0 | Q13: 0 | R13: =(E13+E13+F13+F13)/100 -> 0 | S13: 8 | T13: =ROUNDUP(IF(S13=6,Q13*I13*R13*0.22,IF(S13=10,Q13*I13*R13*0.62,Q13*R13*I13*0.4)),0) -> 0
C14: الثاني | D14: c1 | E14: 0 | F14: 0 | G14: 0 | H14: =G14*F14*E14/1000000 -> 0 | I14: 0 | J14: =H14*I14 -> 0 | K14: =J14*8/20 -> 0 | L14: =J14*1.2 -> 0 | M14: 0 | N14: =IF(G14=0,0,G14/100+1) -> 0 | O14: 12 | P14: =ROUNDUP(IF(O14=14,M14*I13*N14*1.2,IF(O14=16,M14*I13*N14*1.59,M14*I13*N14*0.89)),0) -> 0 | Q14: 0 | R14: =(E14+E14+F14+F14)/100 -> 0 | S14: 8 | T14: =ROUNDUP(IF(S14=6,Q14*I14*R14*0.22,IF(S14=10,Q14*I14*R14*0.62,Q14*R14*I14*0.4)),0) -> 0 | U14: =(T14+T15+P14+P15)/1000 -> 0
D15: - | E15: 0 | F15: 0 | G15: 0 | H15: =G15*F15*E15/1000000 -> 0 | I15: 0 | J15: =H15*I15 -> 0 | K15: =J15*8/20 -> 0 | L15: =J15*1.2 -> 0 | M15: 0 | N15: =IF(G15=0,0,G15/100+1) -> 0 | O15: 12 | P15: =ROUNDUP(IF(O15=14,M15*I14*N15*1.2,IF(O15=16,M15*I14*N15*1.59,M15*I14*N15*0.89)),0) -> 0 | Q15: 0 | R15: =(E15+E15+F15+F15)/100 -> 0 | S15: 8 | T15: =ROUNDUP(IF(S15=6,Q15*I15*R15*0.22,IF(S15=10,Q15*I15*R15*0.62,Q15*R15*I15*0.4)),0) -> 0
C16: الإجمالي | J16: =SUM(J8:J14) -> 12.64 | K16: =SUM(K8:K14) -> 5.056 | L16: =SUM(L8:L14) -> 15.168 | M16: 14 mm | N16: =SUMIF(O8:O15,"14",P8:P15)/1000 -> 0 | O16: 12 mm | P16: =SUMIF(O8:O15,"12",P8:P15)/1000 -> 0.67 | Q16: 8 mm | R16: =SUMIF(S8:S15,"8",T8:T15)/1000 -> 0.312 | S16: 6 mm | T16: =SUMIF(S8:S15,"6",T8:T15)/1000 -> 0 | U16: =SUM(U8:U15) -> 0.982
C19: الكلفة التفصيلية
C20: اسمنت | D20: =K16*sumry!E7 -> 657.28
C21: بحص / رمل | D21: =L16*sumry!E8 -> 203.9395
C22: حديد | D22: =(N16*sumry!E4+Columns!P16*sumry!E4+Columns!R16*sumry!E5+Columns!T16*sumry!E6) -> 644.31
C23: تنفيذ | D23: =SUM(I8:I15)*(sumry!H6+sumry!H11) -> 675.63025
C24: الإجمالي | D24: =SUM(D20:D23) -> 2181.1597

Sheet Beams
C3: الشيناجات
C4: البيتون | L4: الحديد
C5: الجائز | D5: الأبعاد | G5: حجم الشيناج | H5: عدد الشيناجات | I5: الحجم الكلي | J5: كمية الاسمنت اللازمة | K5: بحص + رمل | L5: التسليح الرئيسي | P5: التسليح الثانوي | T5: اجمالي كمية التسليح
D6: الطول | E6: العرض | F6: السماكة | L6: عدد الاسياخ | M6: طول السيخ | N6: القطر | O6: كمية التسليح | P6: عدد الاسياخ | Q6: طول السيخ | R6: القطر | S6: كمية التسليح
D7: m | E7: cm | F7: cm | G7: m3 | H7: n | I7: m3 | J7: ton | K7: m3 | L7: n | M7: m | N7: mm | O7: kg | P7: n | Q7: m | R7: mm | S7: kg | T7: ton
C8: B1 | D8: 0 | E8: 0 | F8: 0 | G8: =F8*E8*D8/10000 -> 0 | H8: 0 | I8: =G8*H8 -> 0 | J8: =I8*7/20 -> 0 | K8: =I8*1.2 -> 0 | L8: 5 | M8: =D8 -> 0 | N8: 12 | O8: =ROUNDUP(IF(N8=14,L8*H8*M8*1.2,IF(N8=16,L8*H8*M8*1.59,L8*H8*M8*0.89)),0) -> 0 | P8: =M8*5 -> 0 | Q8: 1.5 | R8: 8 | S8: =ROUNDUP(IF(R8=6,P8*H8*Q8*0.22,IF(R8=10,P8*H8*Q8*0.62,P8*Q8*H8*0.4)),0) -> 0 | T8: =(S8+O8)/1000 -> 0
C9: B2 | D9: 0 | E9: 0 | F9: 0 | G9: =F9*E9*D9/10000 -> 0 | H9: 0 | I9: =G9*H9 -> 0 | J9: =I9*7/20 -> 0 | K9: =I9*1.2 -> 0 | L9: 5 | M9: =D9 -> 0 | N9: 12 | O9: =ROUNDUP(IF(N9=14,L9*H9*M9*1.2,IF(N9=16,L9*H9*M9*1.59,L9*H9*M9*0.89)),0) -> 0 | P9: =M9*5 -> 0 | Q9: 1.5 | R9: 8 | S9: =ROUNDUP(IF(R9=6,P9*H9*Q9*0.22,IF(R9=10,P9*H9*Q9*0.62,P9*Q9*H9*0.4)),0) -> 0 | T9: =(S9+O9)/1000 -> 0
C10: B3 | D10: 0 | E10: 0 | F10: 0 | G10: =F10*E10*D10/10000 -> 0 | H10: 0 | I10: =G10*H10 -> 0 | J10: =I10*7/20 -> 0 | K10: =I10*1.2 -> 0 | L10: 5 | M10: =D10 -> 0 | N10: 12 | O10: =ROUNDUP(IF(N10=14,L10*H10*M10*1.2,IF(N10=16,L10*H10*M10*1.59,L10*H10*M10*0.89)),0) -> 0 | P10: =M10*5 -> 0 | Q10: 1.5 | R10: 8 | S10: =ROUNDUP(IF(R10=6,P10*H10*Q10*0.22,IF(R10=10,P10*H10*Q10*0.62,P10*Q10*H10*0.4)),0) -> 0 | T10: =(S10+O10)/1000 -> 0
C11: B4 | D11: 0 | E11: 0 | F11: 0 | G11: =F11*E11*D11/10000 -> 0 | H11: 0 | I11: =G11*H11 -> 0 | J11: =I11*7/20 -> 0 | K11: =I11*1.2 -> 0 | L11: 5 | M11: =D11 -> 0 | N11: 12 | O11: =ROUNDUP(IF(N11=14,L11*H11*M11*1.2,IF(N11=16,L11*H11*M11*1.59,L11*H11*M11*0.89)),0) -> 0 | P11: =M11*5 -> 0 | Q11: 1.5 | R11: 8 | S11: =ROUNDUP(IF(R11=6,P11*H11*Q11*0.22,IF(R11=10,P11*H11*Q11*0.62,P11*Q11*H11*0.4)),0) -> 0 | T11: =(S11+O11)/1000 -> 0
C12: B5 | D12: 0 | E12: 0 | F12: 0 | G12: =F12*E12*D12/10000 -> 0 | H12: 0 | I12: =G12*H12 -> 0 | J12: =I12*7/20 -> 0 | K12: =I12*1.2 -> 0 | L12: 0 | M12: =D12 -> 0 | N12: 12 | O12: =ROUNDUP(IF(N12=14,L12*H12*M12*1.2,IF(N12=16,L12*H12*M12*1.59,L12*H12*M12*0.89)),0) -> 0 | P12: =M12*5 -> 0 | Q12: 0 | R12: 8 | S12: =ROUNDUP(IF(R12=6,P12*H12*Q12*0.22,IF(R12=10,P12*H12*Q12*0.62,P12*Q12*H12*0.4)),0) -> 0 | T12: =(S12+O12)/1000 -> 0
C13: B6 | D13: 0 | E13: 0 | F13: 0 | G13: =F13*E13*D13/10000 -> 0 | H13: 0 | I13: =G13*H13 -> 0 | J13: =I13*7/20 -> 0 | K13: =I13*1.2 -> 0 | L13: 0 | M13: =D13 -> 0 | N13: 12 | O13: =ROUNDUP(IF(N13=14,L13*H13*M13*1.2,IF(N13=16,L13*H13*M13*1.59,L13*H13*M13*0.89)),0) -> 0 | P13: =M13*5 -> 0 | Q13: 0 | R13: 8 | S13: =ROUNDUP(IF(R13=6,P13*H13*Q13*0.22,IF(R13=10,P13*H13*Q13*0.62,P13*Q13*H13*0.4)),0) -> 0 | T13: =(S13+O13)/1000 -> 0
C14: الإجمالي | I14: =SUM(I8:I13) -> 0 | J14: =SUM(J8:J13) -> 0 | K14: =SUM(K8:K13) -> 0 | L14: 14 mm | M14: =SUMIF(N6:N13,"14",O6:O13)/1000 -> 0 | N14: 12 mm | O14: =SUMIF(N6:N13,"12",O6:O13)/1000 -> 0 | P14: 8 mm | Q14: =SUMIF(R6:R13,"8",S6:S13)/1000 -> 0 | R14: 6 mm | S14: =SUMIF(R6:R13,"6",S6:S13)/1000 -> 0 | T14: =SUM(T6:T13) -> 0
C17: الكلفة التفصيلية
C18: اسمنت | D18: =J14*sumry!E7 -> 0
C19: بحص / رمل | D19: =K14*sumry!E8 -> 0
C20: حديد | D20: =M14*sumry!E4+Beams!O14*sumry!E4+Beams!Q14*sumry!E5+Beams!S14*sumry!E6 -> 0
C21: تنفيذ | D21: =IF(SUM(D8:D13)=0,0,SUM(D8:D13)/3*sumry!H4+sumry!H9) -> 0
C22: الإجمالي | D22: =SUM(D18:D21) -> 0

Sheet Slaps
C3: الأرضية
C4: البيتون | I4: الحديد
C5: الأبعاد | F5: حجم الأرضية | G5: كمية الاسمنت اللازمة | H5: بحص + رمل | I5: التسليح الرئيسي | M5: التسليح الثانوي | Q5: اجمالي كمية التسليح
C6: الطول | D6: العرض | E6: السماكة | I6: عدد الاسياخ | J6: طول السيخ | K6: القطر | L6: كمية التسليح | M6: عدد الاسياخ | N6: طول السيخ | O6: القطر | P6: كمية التسليح
C7: m | D7: m | E7: cm | F7: m3 | G7: ton | H7: m3 | I7: n | J7: m | K7: mm | L7: kg | M7: n | N7: m | O7: mm | P7: kg | Q7: ton
C8: 0 | D8: 0 | E8: 0 | F8: =E8*D8*C8/100 -> 0 | G8: =F8*7/20 -> 0 | H8: =F8*1.2 -> 0 | I8: =ROUNDUP(C8*4.5,0) -> 0 | J8: =D8 -> 0 | K8: 10 | L8: =ROUNDUP(IF(K8=12,I8*J8*0.89,IF(K8=8,I8*J8*0.4,I8*J8*0.62)),0) -> 0 | M8: =ROUNDUP(D8*4,0) -> 0 | N8: =C8 -> 0 | O8: 8 | P8: =ROUNDUP(IF(O8=6,M8*N8*0.22,IF(O8=10,M8*N8*0.62,M8*N8*0.4)),0) -> 0 | Q8: =(P8+L8)/1000 -> 0
C9: الإجمالي | G9: =SUM(G8:G8) -> 0 | H9: =SUM(H8:H8) -> 0 | I9: 12mm | J9: =IF(K8=12,L8,0)/1000 -> 0 | K9: 10mm | L9: =IF(K8=10,IF(O8=10,L8+P8,IF(K8=10,L8,0)),IF(O8=10,P8,0))/1000 -> 0 | M9: 8mm | N9: =IF(K8=8,IF(O8=8,L8+P8,IF(K8=8,L8,0)),IF(O8=8,P8,0))/1000 -> 0 | O9: 6mm | P9: =IF(K8=6,IF(O8=6,L8+P8,IF(K8=6,L8,0)),IF(O8=6,P8,0))/1000 -> 0
C11: الكلفة التفصيلية
C12: اسمنت | D12: =G9*sumry!E7 -> 0
C13: بحص / رمل | D13: =H9*sumry!E8 -> 0
C14: حديد | D14: =J9*sumry!E4+Slaps!L9*sumry!E5+Slaps!N9*sumry!E5+Slaps!P9*sumry!E6 -> 0
C15: تنفيذ | D15: =IF(F8=0,0,F8*sumry!H4+sumry!H10) -> 0
C16: الإجمالي | D16: =SUM(D12:D15) -> 0
C20: البلاطات
C21: البيتون | K21: الحديد
C22: الأبعاد | F22: حجم البلاطة | G22: كمية البلوك | H22: حجم الخرسانة | I22: كمية الاسمنت اللازمة | J22: بحص + رمل | K22: العنصر | L22: العدد | M22: التسليح الرئيسي | Q22: التسليح الثانوي
C23: الطول | D23: العرض | E23: السماكة | M23: عدد الأسياخ | N23: طول السيخ | O23: قطر السيخ | P23: كمية التسليح | Q23: عدد الأسياخ | R23: طول السيخ | S23: قطر السيخ | T23: كمية التسليح | U23: اجمالي التسليح
C24: m | D24: m | E24: cm | F24: m3 | G24: n | H24: m3 | I24: ton | J24: m3 | L24: n | M24: n | N24: m | O24: mm | P24: Kg | Q24: n | R24: m | S24: mm | T24: Kg | U24: ton
C25: 15.2 | D25: 12.8 | E25: 26 | F25: =E25*D25*C25/100 -> 50.5856 | G25: =ROUNDUP((F25*0.34)/(0.2*0.4*0.2),0) -> 1075 | H25: =F25*0.67 -> 33.892352 | I25: =H25*7/20 -> 11.862323 | J25: =H25*1.2 -> 40.670822 | K25: البلاطة | L25: 1 | M25: 21 | N25: 18 | O25: 6 | P25: =ROUNDUP(IF(O25=10,N25*M25*L25*0.62,IF(O25=8,N25*M25*L25*0.4,IF(O25=6,N25*M25*L25*0.22))),0) -> 84 | Q25: 75 | R25: 12 | S25: 6 | T25: =ROUNDUP(IF(S25=10,R25*L25*Q25*0.62,IF(S25=8,R25*L25*Q25*0.4,IF(S25=6,R25*L25*Q25*0.22))),0) -> 198 | U25: =(T25+P25)/1000 -> 0.282
C26: 0 | D26: 0 | E26: 0 | F26: =E26*D26*C26/100 -> 0 | G26: =ROUNDUP((F26*0.34)/(0.2*0.4*0.2),0) -> 0 | H26: =F26*0.67 -> 0 | I26: =H26*7/20 -> 0 | J26: =H26*1.2 -> 0 | K26: الأعصاب | L26: 6 | M26: 3 | N26: 22 | O26: 12 | P26: =ROUNDUP(IF(O26=12,N26*M26*L26*0.89,IF(O26=14,N26*L26*M26*1.2,IF(O26=16,N26*L26*M26*1.59))),0) -> 353 | Q26: =IF(N26=0,0,ROUNDUP(N26*5+1,0)) -> 111 | R26: 0.65 | S26: 6 | T26: =ROUNDUP(IF(S26=10,R26*L26*Q26*0.62,IF(S26=8,R26*L26*Q26*0.4,IF(S26=6,R26*L26*Q26*0.22))),0) -> 96 | U26: =(T26+P26)/1000 -> 0.449
C27: 0 | D27: 0 | E27: 0 | F27: =E27*D27*C27/100 -> 0 | G27: =ROUNDUP((F27*0.34)/(0.2*0.4*0.2),0) -> 0 | H27: =F27*0.67 -> 0 | I27: =H27*7/20 -> 0 | J27: =H27*1.2 -> 0 | L27: 12 | M27: 3 | N27: 12 | O27: 12 | P27: =ROUNDUP(IF(O27=12,N27*M27*L27*0.89,IF(O27=14,N27*L27*M27*1.2,IF(O27=16,N27*L27*M27*1.59))),0) -> 385 | Q27: =IF(N27=0,0,ROUNDUP(N27*5+1,0)) -> 61 | R27: 0.65 | S27: 6 | T27: =ROUNDUP(IF(S27=10,R27*L27*Q27*0.62,IF(S27=8,R27*L27*Q27*0.4,IF(S27=6,R27*L27*Q27*0.22))),0) -> 105 | U27: =(T27+P27)/1000 -> 0.49
C28: 0 | D28: 0 | E28: 0 | F28: =E28*D28*C28/100 -> 0 | G28: =ROUNDUP((F28*0.34)/(0.2*0.4*0.2),0) -> 0 | H28: =F28*0.67 -> 0 | I28: =H28*7/20 -> 0 | J28: =H28*1.2 -> 0 | L28: 1 | M28: 4 | N28: 34 | O28: 12 | P28: =ROUNDUP(IF(O28=12,N28*M28*L28*0.89,IF(O28=14,N28*L28*M28*1.2,IF(O28=16,N28*L28*M28*1.59))),0) -> 122 | Q28: =IF(N28=0,0,ROUNDUP(N28*5+1,0)) -> 171 | R28: 0.75 | S28: 6 | T28: =ROUNDUP(IF(S28=10,R28*L28*Q28*0.62,IF(S28=8,R28*L28*Q28*0.4,IF(S28=6,R28*L28*Q28*0.22))),0) -> 29 | U28: =(T28+P28)/1000 -> 0.151
C29: 0 | D29: 0 | E29: 0 | F29: =E29*D29*C29/100 -> 0 | G29: =ROUNDUP((F29*0.34)/(0.2*0.4*0.2),0) -> 0 | H29: =F29*0.67 -> 0 | I29: =H29*7/20 -> 0 | J29: =H29*1.2 -> 0 | K29: الأعصاب العريضة | L29: 2 | M29: 6 | N29: 16 | O29: 12 | P29: =ROUNDUP(IF(O29=12,N29*M29*L29*0.89,IF(O29=14,N29*L29*M29*1.2,IF(O29=16,N29*L29*M29*1.59))),0) -> 171 | Q29: =IF(N29=0,0,ROUNDUP(N29*5+1,0)) -> 81 | R29: 1.3 | S29: 8 | T29: =ROUNDUP(IF(S29=10,R29*L29*Q29*0.62,IF(S29=8,R29*L29*Q29*0.4,IF(S29=6,R29*L29*Q29*0.22))),0) -> 85 | U29: =(T29+P29)/1000 -> 0.256
C30: 0 | D30: 0 | E30: 0 | F30: =E30*D30*C30/100 -> 0 | G30: =ROUNDUP((F30*0.34)/(0.2*0.4*0.2),0) -> 0 | H30: =F30*0.67 -> 0 | I30: =H30*7/20 -> 0 | J30: =H30*1.2 -> 0 | L30: 1 | M30: 6 | N30: 12 | O30: 12 | P30: =ROUNDUP(IF(O30=12,N30*M30*L30*0.89,IF(O30=14,N30*L30*M30*1.2,IF(O30=16,N30*L30*M30*1.59))),0) -> 65 | Q30: =IF(N30=0,0,ROUNDUP(N30*5+1,0)) -> 61 | R30: 1.3 | S30: 8 | T30: =ROUNDUP(IF(S30=10,R30*L30*Q30*0.62,IF(S30=8,R30*L30*Q30*0.4,IF(S30=6,R30*L30*Q30*0.22))),0) -> 32 | U30: =(T30+P30)/1000 -> 0.097
C31: 0 | D31: 0 | E31: 0 | F31: =E31*D31*C31/100 -> 0 | G31: =ROUNDUP((F31*0.34)/(0.2*0.4*0.2),0) -> 0 | H31: =F31*0.67 -> 0 | I31: =H31*7/20 -> 0 | J31: =H31*1.2 -> 0 | L31: 3 | M31: 6 | N31: 6 | O31: 12 | P31: =ROUNDUP(IF(O31=12,N31*M31*L31*0.89,IF(O31=14,N31*L31*M31*1.2,IF(O31=16,N31*L31*M31*1.59))),0) -> 97 | Q31: =IF(N31=0,0,ROUNDUP(N31*5+1,0)) -> 31 | R31: 1.3 | S31: 8 | T31: =ROUNDUP(IF(S31=10,R31*L31*Q31*0.62,IF(S31=8,R31*L31*Q31*0.4,IF(S31=6,R31*L31*Q31*0.22))),0) -> 49 | U31: =(T31+P31)/1000 -> 0.146
C32: 0 | D32: 0 | E32: 0 | F32: =E32*D32*C32/100 -> 0 | G32: =ROUNDUP((F32*0.34)/(0.2*0.4*0.2),0) -> 0 | H32: =F32*0.67 -> 0 | I32: =H32*7/20 -> 0 | J32: =H32*1.2 -> 0 | K32: الجوائز | L32: 3 | M32: 12 | N32: 14 | O32: 12 | P32: =ROUNDUP(IF(O32=12,N32*M32*L32*0.89,IF(O32=14,N32*L32*M32*1.2,IF(O32=16,N32*L32*M32*1.59))),0) -> 449 | Q32: =IF(N32=0,0,ROUNDUP(N32*5+1,0)) -> 71 | R32: 3 | S32: 8 | T32: =ROUNDUP(IF(S32=10,R32*L32*Q32*0.62,IF(S32=8,R32*L32*Q32*0.4,IF(S32=6,R32*L32*Q32*0.22))),0) -> 256 | U32: =(T32+P32)/1000 -> 0.705
C33: 0 | D33: 0 | E33: 0 | F33: =E33*D33*C33/100 -> 0 | G33: =ROUNDUP((F33*0.34)/(0.2*0.4*0.2),0) -> 0 | H33: =F33*0.67 -> 0 | I33: =H33*7/20 -> 0 | J33: =H33*1.2 -> 0 | L33: 1 | M33: 12 | N33: 7 | O33: 12 | P33: =ROUNDUP(IF(O33=12,N33*M33*L33*0.89,IF(O33=14,N33*L33*M33*1.2,IF(O33=16,N33*L33*M33*1.59))),0) -> 75 | Q33: =IF(N33=0,0,ROUNDUP(N33*5+1,0)) -> 36 | R33: 3 | S33: 8 | T33: =ROUNDUP(IF(S33=10,R33*L33*Q33*0.62,IF(S33=8,R33*L33*Q33*0.4,IF(S33=6,R33*L33*Q33*0.22))),0) -> 44 | U33: =(T33+P33)/1000 -> 0.119
C34: 0 | D34: 0 | E34: 0 | F34: =E34*D34*C34/100 -> 0 | G34: =ROUNDUP((F34*0.34)/(0.2*0.4*0.2),0) -> 0 | H34: =F34*0.67 -> 0 | I34: =H34*7/20 -> 0 | J34: =H34*1.2 -> 0 | L34: 1 | M34: 12 | N34: 6 | O34: 12 | P34: =ROUNDUP(IF(O34=12,N34*M34*L34*0.89,IF(O34=14,N34*L34*M34*1.2,IF(O34=16,N34*L34*M34*1.59))),0) -> 65 | Q34: =IF(N34=0,0,ROUNDUP(N34*5+1,0)) -> 31 | R34: 3 | S34: 8 | T34: =ROUNDUP(IF(S34=10,R34*L34*Q34*0.62,IF(S34=8,R34*L34*Q34*0.4,IF(S34=6,R34*L34*Q34*0.22))),0) -> 38 | U34: =(T34+P34)/1000 -> 0.103
C35: الإجمالي | F35: =SUM(F25:F34) -> 50.5856 | G35: =SUM(G25:G34) -> 1075 | H35: =SUM(H25:H34) -> 33.892352 | I35: =SUM(I25:I34) -> 11.862323 | J35: =SUM(J25:J34) -> 40.670822 | K35: 14mm | L35: =SUMIF(O26:O34,"14",P26:P34)/1000 -> 0 | M35: 12mm | N35: =SUMIF(O26:O34,"12",P26:P34)/1000 -> 1.782 | O35: 10mm | P35: =(SUMIF($O$25,"10",$P$25)+SUMIF($S$25:$S$34,"10",$T$25:$T$34))/1000 -> 0 | Q35: 8mm | R35: =(SUMIF($O$25,"8",$P$25)+SUMIF($S$25:$S$34,"8",$T$25:$T$34))/1000 -> 0.504 | S35: 6mm | T35: =(SUMIF($O$25,"6",$P$25)+SUMIF($S$25:$S$34,"6",$T$25:$T$34))/1000 -> 0.512 | U35: =SUM(U25:U34) -> 2.798
C38: الكلفة التفصيلية
C39: اسمنت | D39: =I35*sumry!E7 -> 1542.102
C40: بحص / رمل | D40: =J35*sumry!E8 -> 546.83459
C41: حديد | D41: =Slaps!L35*sumry!E4+Slaps!N35*sumry!E4+Slaps!P35*sumry!E5+Slaps!R35*sumry!E5+Slaps!T35*sumry!E6 -> 1855.63
C42: هوردي | D42: =G35*sumry!E9 -> 496.84874
C43: تنفيذ | D43: =IF(H35=0,0,H35*sumry!H4+sumry!H10) -> 594.5771
C44: الإجمالي | D44: =SUM(D39:D43) -> 5035.9924

Sheet Stairs
C3: الدرج
C4: البيتون
C5: الميدة | E5: الدرجة | G5: الشاحط الأول | I5: الشاحط الثاني | K5: حجم الدرج | L5: كمية الاسمنت اللازمة | M5: كمية البحص والرمل | N5: عدد الطوابق | Q5: =IF(F7=0,0,(J6+H6)*100/F7+1) -> 21
C6: طول (m) | D6: 2.5 | E6: قائمة (cm) | F6: 16 | G6: طول (m) | H6: 3 | I6: طول (m) | J6: 3 | K6: =Q16+Q15+Q13 -> 2.3904 | L6: =K6*7/20 -> 0.83664 | M6: =K6*1.2 -> 2.86848 | N6: 1 | Q6: =F6*F6+F7*F7 -> 1156
C7: عرض (m) | D7: 1.2 | E7: نائمة (cm) | F7: 30 | G7: عرض (m) | H7: 1.2 | I7: عرض (m) | J7: 1.2 | Q7: =SQRT(Q6) -> 34
C8: سماكة (cm) | D8: 16 | E8: عدد الدرجات | F8: =Q5 -> 21 | G8: سماكة (cm) | H8: 16 | I8: سماكة (cm) | J8: 16 | Q8: =IF(F7=0,0,Q7/F7) -> 1.1333333
C9: الإجمالي | L9: =L6*N6 -> 0.83664 | M9: =M6*N6 -> 2.86848 | Q9: =Q8*H6 -> 3.4
C11: الحديد | Q11: =Q8*J6 -> 3.4
C12: تشاريك الشيناج | G12: تسليح الشواحط | K12: تسليح الميدة
C13: العدد | D13: القطر | E13: الطول | F13: كمية التسليح | G13: العدد | H13: القطر | I13: الطول | J13: كمية التسليح | K13: العدد | L13: القطر | M13: الطول | N13: كمية التسليح | Q13: =D6*D7*D8/100 -> 0.48
C14: 10 | D14: 0 | E14: 0 | F14: =E14*C14*0.89 -> 0 | G14: =C14 -> 10 | H14: 12 | I14: =Q9+Q11+D7+D7+D7 -> 10.4 | J14: =I14*G14*0.89 -> 92.56 | K14: =ROUNDUP(D7*5,0) -> 6 | L14: 12 | M14: =D6 -> 2.5 | N14: =M14*K14*0.89 -> 13.35 | Q14: =F6*F7*H7/2/10000 -> 0.0288
G15: =F8 -> 21 | H15: 12 | I15: =H7 -> 1.2 | J15: =I15*G15*0.89 -> 22.428 | Q15: =Q14*F8 -> 0.6048
C16: الإجمالي للطابق | G16: =(N14+J15+J14+F14)/1000 -> 0.128338 | I16: الإجمالي للمبنى | M16: =(N14+J15+J14+F14)/1000*N6 -> 0.128338 | Q16: =(Q9+Q11)*H7*H8/100 -> 1.3056
C19: الكلفة التفصيلية
C20: اسمنت | D20: =L9*sumry!E7 -> 108.7632
C21: بحص / رمل | D21: =M9*sumry!E8 -> 38.567798
C22: حديد | D22: =M16*sumry!E4 -> 82.77801
C23: تنفيذ | D23: =IF(M16=0,0,N6*(sumry!H7+50)) -> 218.06723
C24: الإجمالي | D24: =SUM(D20:D23) -> 448.17624

Sheet Bricks
C3: البلوك
C4: الطابق | D4: نوع الجدار | E4: طول الجدار | F4: ارتفاع الجدار | G4: سماكة الجدار | H4: عدد الأبواب | I4: عدد الشبابيك | J4: سماكة البلوكة | L4: كمية البلوك اللازمة | N4: كمية الاسمنت اللازمة | O4: كمية الرمل اللازمة
J5: خارجي | K5: داخلي | L5: خارجي | M5: داخلي
E6: m | F6: m | G6: cm | H6: n | I6: n | J6: cm | K6: cm | L6: n | M6: n | N6: ton | O6: m3
C7: الأرضي | D7: خارجي | E7: 0 | F7: 0 | G7: 0 | H7: 0 | I7: 0 | J7: 0 | K7: =IF(G7=0,0,IF(J7=0,0,G7-J7-5)) -> 0 | L7: =ROUNDUP((E7*F7-(H7*2.35+I7*1.8))/0.08,0) -> 0 | M7: =ROUNDUP((E7*F7-(H7*2.35+I7*1.8))/0.08,0) -> 0 | N7: =M7/100/20+L7/100/20 -> 0 | O7: =N7*20/7 -> 0 | Q7: =E7*F7*2 -> 0
D8: داخلي | E8: 0 | F8: 0 | G8: 0 | H8: 0 | I8: 0 | J8: =G8 -> 0 | L8: =ROUNDUP((E8*F8-(H8*2.35+I8*1.8))/0.08,0) -> 0 | N8: =L8/100/20 -> 0 | O8: =N8*20/7 -> 0 | Q8: =E8*F8 -> 0
D9: تصوينة | E9: 0 | F9: 0 | G9: 0 | H9: 0 | I9: 0 | J9: =G9 -> 0 | L9: =ROUNDUP((E9*F9-(H9*2.35+I9*1.8))/0.08,0) -> 0 | N9: =L9/100/20 -> 0 | O9: =N9*20/7 -> 0 | Q9: =E9*F9 -> 0
C10: الأول | D10: خارجي | E10: 0 | F10: 0 | G10: 0 | H10: 0 | I10: 0 | J10: 0 | K10: =IF(G10=0,0,IF(J10=0,0,G10-J10-5)) -> 0 | L10: =ROUNDUP((E10*F10-(H10*2.35+I10*1.8))/0.08,0) -> 0 | M10: =ROUNDUP((E10*F10-(H10*2.35+I10*1.8))/0.08,0) -> 0 | N10: =M10/100/20+L10/100/20 -> 0 | O10: =N10*20/7 -> 0 | Q10: =E10*F10*2 -> 0
D11: داخلي | E11: 0 | F11: 0 | G11: 0 | H11: 0 | I11: 0 | J11: =G11 -> 0 | L11: =ROUNDUP((E11*F11-(H11*2.35+I11*1.8))/0.08,0) -> 0 | N11: =L11/100/20 -> 0 | O11: =N11*20/7 -> 0 | Q11: =E11*F11 -> 0
D12: تصوينة | E12: 0 | F12: 0 | G12: 0 | H12: 0 | I12: 0 | J12: =G12 -> 0 | L12: =ROUNDUP((E12*F12-(H12*2.35+I12*1.8))/0.08,0) -> 0 | N12: =L12/100/20 -> 0 | O12: =N12*20/7 -> 0 | Q12: =E12*F12 -> 0
C13: الثاني | D13: خارجي | E13: 0 | F13: 0 | G13: 0 | H13: 0 | I13: 0 | J13: 0 | K13: =IF(G13=0,0,IF(J13=0,0,G13-J13-5)) -> 0 | L13: =ROUNDUP((E13*F13-(H13*2.35+I13*1.8))/0.08,0) -> 0 | M13: =ROUNDUP((E13*F13-(H13*2.35+I13*1.8))/0.08,0) -> 0 | N13: =M13/100/20+L13/100/20 -> 0 | O13: =N13*20/7 -> 0 | Q13: =E13*F13*2 -> 0
D14: داخلي | E14: 0 | F14: 0 | G14: 0 | H14: 0 | I14: 0 | J14: =G14 -> 0 | L14: =ROUNDUP((E14*F14-(H14*2.35+I14*1.8))/0.08,0) -> 0 | N14: =L14/100/20 -> 0 | O14: =N14*20/7 -> 0 | Q14: =E14*F14 -> 0
D15: تصوينة | E15: 0 | F15: 0 | G15: 0 | H15: 0 | I15: 0 | J15: =G15 -> 0 | L15: =ROUNDUP((E15*F15-(H15*2.35+I15*1.8))/0.08,0) -> 0 | N15: =L15/100/20 -> 0 | O15: =N15*20/7 -> 0 | Q15: =E15*F15 -> 0
C16: الثالث | D16: خارجي | E16: 0 | F16: 0 | G16: 0 | H16: 0 | I16: 0 | J16: 0 | K16: =IF(G16=0,0,IF(J16=0,0,G16-J16-5)) -> 0 | L16: =ROUNDUP((E16*F16-(H16*2.35+I16*1.8))/0.08,0) -> 0 | M16: =ROUNDUP((E16*F16-(H16*2.35+I16*1.8))/0.08,0) -> 0 | N16: =M16/100/20+L16/100/20 -> 0 | O16: =N16*20/7 -> 0 | Q16: =E16*F16*2 -> 0
D17: داخلي | E17: 0 | F17: 0 | G17: 0 | H17: 0 | I17: 0 | J17: =G17 -> 0 | L17: =ROUNDUP((E17*F17-(H17*2.35+I17*1.8))/0.08,0) -> 0 | N17: =L17/100/20 -> 0 | O17: =N17*20/7 -> 0 | Q17: =E17*F17 -> 0
D18: تصوينة | E18: 0 | F18: 0 | G18: 0 | H18: 0 | I18: 0 | J18: =G18 -> 0 | L18: =ROUNDUP((E18*F18-(H18*2.35+I18*1.8))/0.08,0) -> 0 | N18: =L18/100/20 -> 0 | O18: =N18*20/7 -> 0 | Q18: =E18*F18 -> 0
C19: السطح الأخير | D19: بيت الدرج | E19: 0 | F19: 0 | G19: 0 | H19: 0 | I19: 0 | J19: =G19 -> 0 | L19: =ROUNDUP((E19*F19-(H19*2.35+I19*1.8))/0.08,0) -> 0 | N19: =L19/100/20 -> 0 | O19: =N19*20/7 -> 0 | Q19: =E19*F19 -> 0
D20: التصوينة | E20: 0 | F20: 0 | G20: 0 | H20: 0 | I20: 0 | J20: =G20 -> 0 | L20: =ROUNDUP((E20*F20-(H20*2.35+I20*1.8))/0.08,0) -> 0 | N20: =L20/100/20 -> 0 | O20: =N20*20/7 -> 0 | Q20: =E20*F20 -> 0
C21: الإجمالي | H21: =SUM(H7:H20) -> 0 | I21: =SUM(I7:I20) -> 0 | J21: - | L21: =SUM(L7:M20) -> 0 | N21: =SUM(N7:N20) -> 0 | O21: =SUM(O7:O20) -> 0 | Q21: =SUM(Q7:Q20) -> 0
C24: الكلفة التفصيلية
C25: اسمنت | D25: =N21*sumry!E7 -> 0
C26: رمل | D26: =O21*sumry!E11 -> 0
C27: بلوك | D27: =L21*sumry!E10 -> 0
C28: تنفيذ | D28: =IF(L21=0,0,(H21+I21)*5+Q21*0.8+(E9+E12+E15+E18)*0.8+30) -> 0
C29: الإجمالي | D29: =SUM(D25:D28) -> 0

Sheet Plastering
C3: الطينة
C4: الطابق | D4: نوع الجدار | E4: الطول | F4: الارتفاع / العرض | G4: سماكة الطينة | H4: عدد الأبواب | I4: عدد الشبابيك | J4: كمية الاسمنت اللازمة | K4: كمية الرمل اللازمة
E6: m | F6: m | G6: cm | H6: n | I6: n | J6: ton | K6: m3 | M6: A2 | N6: D+W | O6: Anet | P6: V i | Q6: V o | R6: Vci | S6: Vco | T6: Tvc | U6: Vri | V6: Vro | W6: Tvr
C7: الأرضي | D7: خارجي / مكسى حجر | E7: 0 | F7: 0 | G7: 0 | H7: 0 | I7: 0 | J7: =ROUNDUP(T7*29/20,1) -> 0 | K7: =ROUNDUP(W7,1) -> 0 | M7: =E7*F7 -> 0 | N7: =H7*2.35+I7*1.8 -> 0 | O7: =M7-N7 -> 0 | P7: =O7*G7/100 -> 0 | Q7: =O7*G7/200 -> 0 | R7: =P7*1.3/5 -> 0 | S7: =Q7*1.3/4 -> 0 | T7: =S7+R7 -> 0 | U7: =P7*1.3*4/5 -> 0 | V7: =Q7*1.3*3/4 -> 0 | W7: =V7+U7 -> 0
D8: خارجي / طينة | E8: 0 | F8: 0 | G8: 0 | H8: 0 | I8: 0 | J8: =ROUNDUP(T8*29/20,1) -> 0 | K8: =ROUNDUP(W8,1) -> 0 | M8: =E8*F8 -> 0 | N8: =H8*2.35+I8*1.8 -> 0 | O8: =M8-N8 -> 0 | P8: =O8*G8/100 -> 0 | Q8: =O8*G8/100 -> 0 | R8: =P8*1.3/5 -> 0 | S8: =Q8*1.3/4 -> 0 | T8: =S8+R8 -> 0 | U8: =P8*1.3*4/5 -> 0 | V8: =Q8*1.3*3/4 -> 0 | W8: =V8+U8 -> 0
D9: داخلي | E9: 0 | F9: 0 | G9: 0 | H9: 0 | I9: 0 | J9: =ROUNDUP(T9*29/20,1) -> 0 | K9: =ROUNDUP(W9,1) -> 0 | M9: =E9*F9 -> 0 | N9: =H9*2.35+I9*1.8 -> 0 | O9: =M9-N9 -> 0 | P9: =O9*G9/100 -> 0 | Q9: =O9*G9/100 -> 0 | R9: =P9*1.3/5 -> 0 | S9: =Q9*1.3/5 -> 0 | T9: =S9+R9 -> 0 | U9: =P9*1.3*4/5 -> 0 | V9: =Q9*1.3*4/5 -> 0 | W9: =V9+U9 -> 0
D10: السقف | E10: 0 | F10: 0 | G10: 0 | H10: - | J10: =ROUNDUP(T10*29/20,1) -> 0 | K10: =ROUNDUP(W10,1) -> 0 | M10: =E10*F10 -> 0 | N10: 0 | O10: =M10-N10 -> 0 | P10: =O10*G10/100 -> 0 | Q10: =O10*G10/100 -> 0 | R10: =P10*1.3/5 -> 0 | S10: =Q10*1.3/5 -> 0 | T10: =S10+R10 -> 0 | U10: =P10*1.3*4/5 -> 0 | V10: =Q10*1.3*4/5 -> 0 | W10: =V10+U10 -> 0
C11: الأول | D11: خارجي / مكسى حجر | E11: 0 | F11: 0 | G11: 0 | H11: 0 | I11: 0 | J11: =ROUNDUP(T11*29/20,1) -> 0 | K11: =ROUNDUP(W11,1) -> 0 | M11: =E11*F11 -> 0 | N11: =H11*2.35+I11*1.8 -> 0 | O11: =M11-N11 -> 0 | P11: =O11*G11/100 -> 0 | Q11: =O11*G11/200 -> 0 | R11: =P11*1.3/5 -> 0 | S11: =Q11*1.3/4 -> 0 | T11: =S11+R11 -> 0 | U11: =P11*1.3*4/5 -> 0 | V11: =Q11*1.3*3/4 -> 0 | W11: =V11+U11 -> 0
D12: خارجي / طينة | E12: 0 | F12: 0 | G12: 0 | H12: 0 | I12: 0 | J12: =ROUNDUP(T12*29/20,1) -> 0 | K12: =ROUNDUP(W12,1) -> 0 | M12: =E12*F12 -> 0 | N12: =H12*2.35+I12*1.8 -> 0 | O12: =M12-N12 -> 0 | P12: =O12*G12/100 -> 0 | Q12: =O12*G12/100 -> 0 | R12: =P12*1.3/5 -> 0 | S12: =Q12*1.3/4 -> 0 | T12: =S12+R12 -> 0 | U12: =P12*1.3*4/5 -> 0 | V12: =Q12*1.3*3/4 -> 0 | W12: =V12+U12 -> 0
D13: داخلي | E13: 0 | F13: 0 | G13: 0 | H13: 0 | I13: 0 | J13: =ROUNDUP(T13*29/20,1) -> 0 | K13: =ROUNDUP(W13,1) -> 0 | M13: =E13*F13 -> 0 | N13: =H13*2.35+I13*1.8 -> 0 | O13: =M13-N13 -> 0 | P13: =O13*G13/100 -> 0 | Q13: =O13*G13/100 -> 0 | R13: =P13*1.3/5 -> 0 | S13: =Q13*1.3/5 -> 0 | T13: =S13+R13 -> 0 | U13: =P13*1.3*4/5 -> 0 | V13: =Q13*1.3*4/5 -> 0 | W13: =V13+U13 -> 0
D14: السقف | E14: 0 | F14: 0 | G14: 0 | H14: - | J14: =ROUNDUP(T14*29/20,1) -> 0 | K14: =ROUNDUP(W14,1) -> 0 | M14: =E14*F14 -> 0 | N14: 0 | O14: =M14-N14 -> 0 | P14: =O14*G14/100 -> 0 | Q14: =O14*G14/100 -> 0 | R14: =P14*1.3/5 -> 0 | S14: =Q14*1.3/5 -> 0 | T14: =S14+R14 -> 0 | U14: =P14*1.3*4/5 -> 0 | V14: =Q14*1.3*4/5 -> 0 | W14: =V14+U14 -> 0
C15: الثاني | D15: خارجي / مكسى حجر | E15: 0 | F15: 0 | G15: 0 | H15: 0 | I15: 0 | J15: =ROUNDUP(T15*29/20,1) -> 0 | K15: =ROUNDUP(W15,1) -> 0 | M15: =E15*F15 -> 0 | N15: =H15*2.35+I15*1.8 -> 0 | O15: =M15-N15 -> 0 | P15: =O15*G15/100 -> 0 | Q15: =O15*G15/200 -> 0 | R15: =P15*1.3/5 -> 0 | S15: =Q15*1.3/4 -> 0 | T15: =S15+R15 -> 0 | U15: =P15*1.3*4/5 -> 0 | V15: =Q15*1.3*3/4 -> 0 | W15: =V15+U15 -> 0
D16: خارجي / طينة | E16: 0 | F16: 0 | G16: 0 | H16: 0 | I16: 0 | J16: =ROUNDUP(T16*29/20,1) -> 0 | K16: =ROUNDUP(W16,1) -> 0 | M16: =E16*F16 -> 0 | N16: =H16*2.35+I16*1.8 -> 0 | O16: =M16-N16 -> 0 | P16: =O16*G16/100 -> 0 | Q16: =O16*G16/100 -> 0 | R16: =P16*1.3/5 -> 0 | S16: =Q16*1.3/4 -> 0 | T16: =S16+R16 -> 0 | U16: =P16*1.3*4/5 -> 0 | V16: =Q16*1.3*3/4 -> 0 | W16: =V16+U16 -> 0
D17: داخلي | E17: 0 | F17: 0 | G17: 0 | H17: 0 | I17: 0 | J17: =ROUNDUP(T17*29/20,1) -> 0 | K17: =ROUNDUP(W17,1) -> 0 | M17: =E17*F17 -> 0 | N17: =H17*2.35+I17*1.8 -> 0 | O17: =M17-N17 -> 0 | P17: =O17*G17/100 -> 0 | Q17: =O17*G17/100 -> 0 | R17: =P17*1.3/5 -> 0 | S17: =Q17*1.3/5 -> 0 | T17: =S17+R17 -> 0 | U17: =P17*1.3*4/5 -> 0 | V17: =Q17*1.3*4/5 -> 0 | W17: =V17+U17 -> 0
D18: السقف | E18: 0 | F18: 0 | G18: 0 | H18: - | J18: =ROUNDUP(T18*29/20,1) -> 0 | K18: =ROUNDUP(W18,1) -> 0 | M18: =E18*F18 -> 0 | N18: 0 | O18: =M18-N18 -> 0 | P18: =O18*G18/100 -> 0 | Q18: =O18*G18/100 -> 0 | R18: =P18*1.3/5 -> 0 | S18: =Q18*1.3/5 -> 0 | T18: =S18+R18 -> 0 | U18: =P18*1.3*4/5 -> 0 | V18: =Q18*1.3*4/5 -> 0 | W18: =V18+U18 -> 0
C19: الثالث | D19: خارجي / مكسى حجر | E19: 0 | F19: 0 | G19: 0 | H19: 0 | I19: 0 | J19: =ROUNDUP(T19*29/20,1) -> 0 | K19: =ROUNDUP(W19,1) -> 0 | M19: =E19*F19 -> 0 | N19: =H19*2.35+I19*1.8 -> 0 | O19: =M19-N19 -> 0 | P19: =O19*G19/100 -> 0 | Q19: =O19*G19/200 -> 0 | R19: =P19*1.3/5 -> 0 | S19: =Q19*1.3/4 -> 0 | T19: =S19+R19 -> 0 | U19: =P19*1.3*4/5 -> 0 | V19: =Q19*1.3*3/4 -> 0 | W19: =V19+U19 -> 0
D20: خارجي / طينة | E20: 0 | F20: 0 | G20: 0 | H20: 0 | I20: 0 | J20: =ROUNDUP(T20*29/20,1) -> 0 | K20: =ROUNDUP(W20,1) -> 0 | M20: =E20*F20 -> 0 | N20: =H20*2.35+I20*1.8 -> 0 | O20: =M20-N20 -> 0 | P20: =O20*G20/100 -> 0 | Q20: =O20*G20/100 -> 0 | R20: =P20*1.3/5 -> 0 | S20: =Q20*1.3/4 -> 0 | T20: =S20+R20 -> 0 | U20: =P20*1.3*4/5 -> 0 | V20: =Q20*1.3*3/4 -> 0 | W20: =V20+U20 -> 0
D21: داخلي | E21: 0 | F21: 0 | G21: 0 | H21: 0 | I21: 0 | J21: =ROUNDUP(T21*29/20,1) -> 0 | K21: =ROUNDUP(W21,1) -> 0 | M21: =E21*F21 -> 0 | N21: =H21*2.35+I21*1.8 -> 0 | O21: =M21-N21 -> 0 | P21: =O21*G21/100 -> 0 | Q21: =O21*G21/100 -> 0 | R21: =P21*1.3/5 -> 0 | S21: =Q21*1.3/5 -> 0 | T21: =S21+R21 -> 0 | U21: =P21*1.3*4/5 -> 0 | V21: =Q21*1.3*4/5 -> 0 | W21: =V21+U21 -> 0
D22: السقف | E22: 0 | F22: 0 | G22: 0 | H22: - | J22: =ROUNDUP(T22*29/20,1) -> 0 | K22: =ROUNDUP(W22,1) -> 0 | M22: =E22*F22 -> 0 | N22: 0 | O22: =M22-N22 -> 0 | P22: =O22*G22/100 -> 0 | Q22: =O22*G22/100 -> 0 | R22: =P22*1.3/5 -> 0 | S22: =Q22*1.3/5 -> 0 | T22: =S22+R22 -> 0 | U22: =P22*1.3*4/5 -> 0 | V22: =Q22*1.3*4/5 -> 0 | W22: =V22+U22 -> 0
C23: السطح الأخير | D23: بيت الدرج | E23: 0 | F23: 0 | G23: 0 | H23: 0 | I23: 0 | J23: =ROUNDUP(T23*29/20,1) -> 0 | K23: =ROUNDUP(W23,1) -> 0 | M23: =E23*F23 -> 0 | N23: =H23*2.35+I23*1.8 -> 0 | O23: =M23-N23 -> 0 | P23: =O23*G23/100 -> 0 | Q23: =O23*G23/200 -> 0 | R23: =P23*1.3/5 -> 0 | S23: =Q23*1.3/4 -> 0 | T23: =S23+R23 -> 0 | U23: =P23*1.3*4/5 -> 0 | V23: =Q23*1.3*3/4 -> 0 | W23: =V23+U23 -> 0
D24: التصوينة | E24: 0 | F24: 0 | G24: 0 | H24: 0 | I24: 0 | J24: =ROUNDUP(T24*29/20,1) -> 0 | K24: =ROUNDUP(W24,1) -> 0 | M24: =E24*F24 -> 0 | N24: =H24*2.35+I24*1.8 -> 0 | O24: =M24-N24 -> 0 | P24: =O24*G24/100 -> 0 | Q24: =O24*G24/100 -> 0 | R24: =P24*1.3/5 -> 0 | S24: =Q24*1.3/4 -> 0 | T24: =S24+R24 -> 0 | U24: =P24*1.3*4/5 -> 0 | V24: =Q24*1.3*3/4 -> 0 | W24: =V24+U24 -> 0
C25: الإجمالي | H25: =SUM(H7:H24) -> 0 | I25: =SUM(I7:I24) -> 0 | J25: =SUM(J7:J24) -> 0 | K25: =SUM(K7:K24) -> 0 | M25: =SUM(M7:M24) -> 0
O27: =M10+M14+M18+M22 -> 0
C28: الكلفة التفصيلية | O28: =M25-O27 -> 0
C29: اسمنت | D29: =J25*sumry!E7 -> 0 | O29: =O27*2 -> 0
C30: رمل | D30: =K25*sumry!E11 -> 0 | O30: =O29+O28 -> 0
C31: تنفيذ | D31: =O31*10000/sumry!Q4 -> 0 | O31: =O30*2 -> 0
C32: الإجمالي | D32: =SUM(D29:D31) -> 0
